cpu-bind=MASK - dlcgpu21, task  0  0 [12295]: mask 0xc0000300c00003 set
/var/spool/slurm/job19562647/slurm_script: line 11: module: command not found
Traceback (most recent call last):
  File "/work/dlclarge2/alidemaa-dl_lab/conda/miniconda3/envs/dllab/lib/python3.10/site-packages/huggingface_hub/utils/_http.py", line 409, in hf_raise_for_status
    response.raise_for_status()
  File "/work/dlclarge2/alidemaa-dl_lab/conda/miniconda3/envs/dllab/lib/python3.10/site-packages/requests/models.py", line 1026, in raise_for_status
    raise HTTPError(http_error_msg, response=self)
requests.exceptions.HTTPError: 401 Client Error: Unauthorized for url: https://huggingface.co/None/resolve/main/config.json

The above exception was the direct cause of the following exception:

Traceback (most recent call last):
  File "/work/dlclarge2/alidemaa-dl_lab/conda/miniconda3/envs/dllab/lib/python3.10/site-packages/transformers/utils/hub.py", line 470, in cached_files
    hf_hub_download(
  File "/work/dlclarge2/alidemaa-dl_lab/conda/miniconda3/envs/dllab/lib/python3.10/site-packages/huggingface_hub/utils/_validators.py", line 114, in _inner_fn
    return fn(*args, **kwargs)
  File "/work/dlclarge2/alidemaa-dl_lab/conda/miniconda3/envs/dllab/lib/python3.10/site-packages/huggingface_hub/file_download.py", line 1008, in hf_hub_download
    return _hf_hub_download_to_cache_dir(
  File "/work/dlclarge2/alidemaa-dl_lab/conda/miniconda3/envs/dllab/lib/python3.10/site-packages/huggingface_hub/file_download.py", line 1115, in _hf_hub_download_to_cache_dir
    _raise_on_head_call_error(head_call_error, force_download, local_files_only)
  File "/work/dlclarge2/alidemaa-dl_lab/conda/miniconda3/envs/dllab/lib/python3.10/site-packages/huggingface_hub/file_download.py", line 1645, in _raise_on_head_call_error
    raise head_call_error
  File "/work/dlclarge2/alidemaa-dl_lab/conda/miniconda3/envs/dllab/lib/python3.10/site-packages/huggingface_hub/file_download.py", line 1533, in _get_metadata_or_catch_error
    metadata = get_hf_file_metadata(
  File "/work/dlclarge2/alidemaa-dl_lab/conda/miniconda3/envs/dllab/lib/python3.10/site-packages/huggingface_hub/utils/_validators.py", line 114, in _inner_fn
    return fn(*args, **kwargs)
  File "/work/dlclarge2/alidemaa-dl_lab/conda/miniconda3/envs/dllab/lib/python3.10/site-packages/huggingface_hub/file_download.py", line 1450, in get_hf_file_metadata
    r = _request_wrapper(
  File "/work/dlclarge2/alidemaa-dl_lab/conda/miniconda3/envs/dllab/lib/python3.10/site-packages/huggingface_hub/file_download.py", line 286, in _request_wrapper
    response = _request_wrapper(
  File "/work/dlclarge2/alidemaa-dl_lab/conda/miniconda3/envs/dllab/lib/python3.10/site-packages/huggingface_hub/file_download.py", line 310, in _request_wrapper
    hf_raise_for_status(response)
  File "/work/dlclarge2/alidemaa-dl_lab/conda/miniconda3/envs/dllab/lib/python3.10/site-packages/huggingface_hub/utils/_http.py", line 459, in hf_raise_for_status
    raise _format(RepositoryNotFoundError, message, response) from e
huggingface_hub.errors.RepositoryNotFoundError: 401 Client Error. (Request ID: Root=1-6873f197-675d6d44047ac7c863f40546;f41db0c1-39af-4fa8-8e74-8ceaaf87c84d)

Repository Not Found for url: https://huggingface.co/None/resolve/main/config.json.
Please make sure you specified the correct `repo_id` and `repo_type`.
If you are trying to access a private or gated repo, make sure you are authenticated. For more details, see https://huggingface.co/docs/huggingface_hub/authentication
Invalid username or password.

The above exception was the direct cause of the following exception:

Traceback (most recent call last):
  File "/work/dlclarge2/alidemaa-dl_lab/mensa_t2i/lora/predict_lora.py", line 126, in <module>
    run_lora_inference(
  File "/work/dlclarge2/alidemaa-dl_lab/mensa_t2i/lora/predict_lora.py", line 45, in run_lora_inference
    text_encoder = AutoModel.from_pretrained(
  File "/work/dlclarge2/alidemaa-dl_lab/conda/miniconda3/envs/dllab/lib/python3.10/site-packages/transformers/models/auto/auto_factory.py", line 547, in from_pretrained
    config, kwargs = AutoConfig.from_pretrained(
  File "/work/dlclarge2/alidemaa-dl_lab/conda/miniconda3/envs/dllab/lib/python3.10/site-packages/transformers/models/auto/configuration_auto.py", line 1197, in from_pretrained
    config_dict, unused_kwargs = PretrainedConfig.get_config_dict(pretrained_model_name_or_path, **kwargs)
  File "/work/dlclarge2/alidemaa-dl_lab/conda/miniconda3/envs/dllab/lib/python3.10/site-packages/transformers/configuration_utils.py", line 608, in get_config_dict
    config_dict, kwargs = cls._get_config_dict(pretrained_model_name_or_path, **kwargs)
  File "/work/dlclarge2/alidemaa-dl_lab/conda/miniconda3/envs/dllab/lib/python3.10/site-packages/transformers/configuration_utils.py", line 667, in _get_config_dict
    resolved_config_file = cached_file(
  File "/work/dlclarge2/alidemaa-dl_lab/conda/miniconda3/envs/dllab/lib/python3.10/site-packages/transformers/utils/hub.py", line 312, in cached_file
    file = cached_files(path_or_repo_id=path_or_repo_id, filenames=[filename], **kwargs)
  File "/work/dlclarge2/alidemaa-dl_lab/conda/miniconda3/envs/dllab/lib/python3.10/site-packages/transformers/utils/hub.py", line 502, in cached_files
    raise OSError(
OSError: None is not a local folder and is not a valid model identifier listed on 'https://huggingface.co/models'
If this is a private repository, make sure to pass a token having permission to this repo either by logging in with `huggingface-cli login` or by passing `token=<your_token>`
Traceback (most recent call last):
  File "/work/dlclarge2/alidemaa-dl_lab/conda/miniconda3/envs/dllab/lib/python3.10/site-packages/huggingface_hub/utils/_http.py", line 409, in hf_raise_for_status
    response.raise_for_status()
  File "/work/dlclarge2/alidemaa-dl_lab/conda/miniconda3/envs/dllab/lib/python3.10/site-packages/requests/models.py", line 1026, in raise_for_status
    raise HTTPError(http_error_msg, response=self)
requests.exceptions.HTTPError: 401 Client Error: Unauthorized for url: https://huggingface.co/None/resolve/main/config.json

The above exception was the direct cause of the following exception:

Traceback (most recent call last):
  File "/work/dlclarge2/alidemaa-dl_lab/conda/miniconda3/envs/dllab/lib/python3.10/site-packages/transformers/utils/hub.py", line 470, in cached_files
    hf_hub_download(
  File "/work/dlclarge2/alidemaa-dl_lab/conda/miniconda3/envs/dllab/lib/python3.10/site-packages/huggingface_hub/utils/_validators.py", line 114, in _inner_fn
    return fn(*args, **kwargs)
  File "/work/dlclarge2/alidemaa-dl_lab/conda/miniconda3/envs/dllab/lib/python3.10/site-packages/huggingface_hub/file_download.py", line 1008, in hf_hub_download
    return _hf_hub_download_to_cache_dir(
  File "/work/dlclarge2/alidemaa-dl_lab/conda/miniconda3/envs/dllab/lib/python3.10/site-packages/huggingface_hub/file_download.py", line 1115, in _hf_hub_download_to_cache_dir
    _raise_on_head_call_error(head_call_error, force_download, local_files_only)
  File "/work/dlclarge2/alidemaa-dl_lab/conda/miniconda3/envs/dllab/lib/python3.10/site-packages/huggingface_hub/file_download.py", line 1645, in _raise_on_head_call_error
    raise head_call_error
  File "/work/dlclarge2/alidemaa-dl_lab/conda/miniconda3/envs/dllab/lib/python3.10/site-packages/huggingface_hub/file_download.py", line 1533, in _get_metadata_or_catch_error
    metadata = get_hf_file_metadata(
  File "/work/dlclarge2/alidemaa-dl_lab/conda/miniconda3/envs/dllab/lib/python3.10/site-packages/huggingface_hub/utils/_validators.py", line 114, in _inner_fn
    return fn(*args, **kwargs)
  File "/work/dlclarge2/alidemaa-dl_lab/conda/miniconda3/envs/dllab/lib/python3.10/site-packages/huggingface_hub/file_download.py", line 1450, in get_hf_file_metadata
    r = _request_wrapper(
  File "/work/dlclarge2/alidemaa-dl_lab/conda/miniconda3/envs/dllab/lib/python3.10/site-packages/huggingface_hub/file_download.py", line 286, in _request_wrapper
    response = _request_wrapper(
  File "/work/dlclarge2/alidemaa-dl_lab/conda/miniconda3/envs/dllab/lib/python3.10/site-packages/huggingface_hub/file_download.py", line 310, in _request_wrapper
    hf_raise_for_status(response)
  File "/work/dlclarge2/alidemaa-dl_lab/conda/miniconda3/envs/dllab/lib/python3.10/site-packages/huggingface_hub/utils/_http.py", line 459, in hf_raise_for_status
    raise _format(RepositoryNotFoundError, message, response) from e
huggingface_hub.errors.RepositoryNotFoundError: 401 Client Error. (Request ID: Root=1-6873f19f-1aca5bbe5f0d3b4a4123f038;f1533566-3e6a-4e66-8e0d-81043d20f680)

Repository Not Found for url: https://huggingface.co/None/resolve/main/config.json.
Please make sure you specified the correct `repo_id` and `repo_type`.
If you are trying to access a private or gated repo, make sure you are authenticated. For more details, see https://huggingface.co/docs/huggingface_hub/authentication
Invalid username or password.

The above exception was the direct cause of the following exception:

Traceback (most recent call last):
  File "/work/dlclarge2/alidemaa-dl_lab/mensa_t2i/lora/predict_lora.py", line 126, in <module>
    run_lora_inference(
  File "/work/dlclarge2/alidemaa-dl_lab/mensa_t2i/lora/predict_lora.py", line 45, in run_lora_inference
    text_encoder = AutoModel.from_pretrained(
  File "/work/dlclarge2/alidemaa-dl_lab/conda/miniconda3/envs/dllab/lib/python3.10/site-packages/transformers/models/auto/auto_factory.py", line 547, in from_pretrained
    config, kwargs = AutoConfig.from_pretrained(
  File "/work/dlclarge2/alidemaa-dl_lab/conda/miniconda3/envs/dllab/lib/python3.10/site-packages/transformers/models/auto/configuration_auto.py", line 1197, in from_pretrained
    config_dict, unused_kwargs = PretrainedConfig.get_config_dict(pretrained_model_name_or_path, **kwargs)
  File "/work/dlclarge2/alidemaa-dl_lab/conda/miniconda3/envs/dllab/lib/python3.10/site-packages/transformers/configuration_utils.py", line 608, in get_config_dict
    config_dict, kwargs = cls._get_config_dict(pretrained_model_name_or_path, **kwargs)
  File "/work/dlclarge2/alidemaa-dl_lab/conda/miniconda3/envs/dllab/lib/python3.10/site-packages/transformers/configuration_utils.py", line 667, in _get_config_dict
    resolved_config_file = cached_file(
  File "/work/dlclarge2/alidemaa-dl_lab/conda/miniconda3/envs/dllab/lib/python3.10/site-packages/transformers/utils/hub.py", line 312, in cached_file
    file = cached_files(path_or_repo_id=path_or_repo_id, filenames=[filename], **kwargs)
  File "/work/dlclarge2/alidemaa-dl_lab/conda/miniconda3/envs/dllab/lib/python3.10/site-packages/transformers/utils/hub.py", line 502, in cached_files
    raise OSError(
OSError: None is not a local folder and is not a valid model identifier listed on 'https://huggingface.co/models'
If this is a private repository, make sure to pass a token having permission to this repo either by logging in with `huggingface-cli login` or by passing `token=<your_token>`
Traceback (most recent call last):
  File "/work/dlclarge2/alidemaa-dl_lab/conda/miniconda3/envs/dllab/lib/python3.10/site-packages/huggingface_hub/utils/_http.py", line 409, in hf_raise_for_status
    response.raise_for_status()
  File "/work/dlclarge2/alidemaa-dl_lab/conda/miniconda3/envs/dllab/lib/python3.10/site-packages/requests/models.py", line 1026, in raise_for_status
    raise HTTPError(http_error_msg, response=self)
requests.exceptions.HTTPError: 401 Client Error: Unauthorized for url: https://huggingface.co/None/resolve/main/config.json

The above exception was the direct cause of the following exception:

Traceback (most recent call last):
  File "/work/dlclarge2/alidemaa-dl_lab/conda/miniconda3/envs/dllab/lib/python3.10/site-packages/transformers/utils/hub.py", line 470, in cached_files
    hf_hub_download(
  File "/work/dlclarge2/alidemaa-dl_lab/conda/miniconda3/envs/dllab/lib/python3.10/site-packages/huggingface_hub/utils/_validators.py", line 114, in _inner_fn
    return fn(*args, **kwargs)
  File "/work/dlclarge2/alidemaa-dl_lab/conda/miniconda3/envs/dllab/lib/python3.10/site-packages/huggingface_hub/file_download.py", line 1008, in hf_hub_download
    return _hf_hub_download_to_cache_dir(
  File "/work/dlclarge2/alidemaa-dl_lab/conda/miniconda3/envs/dllab/lib/python3.10/site-packages/huggingface_hub/file_download.py", line 1115, in _hf_hub_download_to_cache_dir
    _raise_on_head_call_error(head_call_error, force_download, local_files_only)
  File "/work/dlclarge2/alidemaa-dl_lab/conda/miniconda3/envs/dllab/lib/python3.10/site-packages/huggingface_hub/file_download.py", line 1645, in _raise_on_head_call_error
    raise head_call_error
  File "/work/dlclarge2/alidemaa-dl_lab/conda/miniconda3/envs/dllab/lib/python3.10/site-packages/huggingface_hub/file_download.py", line 1533, in _get_metadata_or_catch_error
    metadata = get_hf_file_metadata(
  File "/work/dlclarge2/alidemaa-dl_lab/conda/miniconda3/envs/dllab/lib/python3.10/site-packages/huggingface_hub/utils/_validators.py", line 114, in _inner_fn
    return fn(*args, **kwargs)
  File "/work/dlclarge2/alidemaa-dl_lab/conda/miniconda3/envs/dllab/lib/python3.10/site-packages/huggingface_hub/file_download.py", line 1450, in get_hf_file_metadata
    r = _request_wrapper(
  File "/work/dlclarge2/alidemaa-dl_lab/conda/miniconda3/envs/dllab/lib/python3.10/site-packages/huggingface_hub/file_download.py", line 286, in _request_wrapper
    response = _request_wrapper(
  File "/work/dlclarge2/alidemaa-dl_lab/conda/miniconda3/envs/dllab/lib/python3.10/site-packages/huggingface_hub/file_download.py", line 310, in _request_wrapper
    hf_raise_for_status(response)
  File "/work/dlclarge2/alidemaa-dl_lab/conda/miniconda3/envs/dllab/lib/python3.10/site-packages/huggingface_hub/utils/_http.py", line 459, in hf_raise_for_status
    raise _format(RepositoryNotFoundError, message, response) from e
huggingface_hub.errors.RepositoryNotFoundError: 401 Client Error. (Request ID: Root=1-6873f1a5-2811652b3718000768f194fb;1b6cbe3d-43ce-46dc-82ea-c70f47f8e685)

Repository Not Found for url: https://huggingface.co/None/resolve/main/config.json.
Please make sure you specified the correct `repo_id` and `repo_type`.
If you are trying to access a private or gated repo, make sure you are authenticated. For more details, see https://huggingface.co/docs/huggingface_hub/authentication
Invalid username or password.

The above exception was the direct cause of the following exception:

Traceback (most recent call last):
  File "/work/dlclarge2/alidemaa-dl_lab/mensa_t2i/lora/predict_lora.py", line 126, in <module>
    run_lora_inference(
  File "/work/dlclarge2/alidemaa-dl_lab/mensa_t2i/lora/predict_lora.py", line 45, in run_lora_inference
    text_encoder = AutoModel.from_pretrained(
  File "/work/dlclarge2/alidemaa-dl_lab/conda/miniconda3/envs/dllab/lib/python3.10/site-packages/transformers/models/auto/auto_factory.py", line 547, in from_pretrained
    config, kwargs = AutoConfig.from_pretrained(
  File "/work/dlclarge2/alidemaa-dl_lab/conda/miniconda3/envs/dllab/lib/python3.10/site-packages/transformers/models/auto/configuration_auto.py", line 1197, in from_pretrained
    config_dict, unused_kwargs = PretrainedConfig.get_config_dict(pretrained_model_name_or_path, **kwargs)
  File "/work/dlclarge2/alidemaa-dl_lab/conda/miniconda3/envs/dllab/lib/python3.10/site-packages/transformers/configuration_utils.py", line 608, in get_config_dict
    config_dict, kwargs = cls._get_config_dict(pretrained_model_name_or_path, **kwargs)
  File "/work/dlclarge2/alidemaa-dl_lab/conda/miniconda3/envs/dllab/lib/python3.10/site-packages/transformers/configuration_utils.py", line 667, in _get_config_dict
    resolved_config_file = cached_file(
  File "/work/dlclarge2/alidemaa-dl_lab/conda/miniconda3/envs/dllab/lib/python3.10/site-packages/transformers/utils/hub.py", line 312, in cached_file
    file = cached_files(path_or_repo_id=path_or_repo_id, filenames=[filename], **kwargs)
  File "/work/dlclarge2/alidemaa-dl_lab/conda/miniconda3/envs/dllab/lib/python3.10/site-packages/transformers/utils/hub.py", line 502, in cached_files
    raise OSError(
OSError: None is not a local folder and is not a valid model identifier listed on 'https://huggingface.co/models'
If this is a private repository, make sure to pass a token having permission to this repo either by logging in with `huggingface-cli login` or by passing `token=<your_token>`
